Workbook

Sheet Read me
A1: Corner Lands rework: steps 0 and 1
A3: What this is | B3: A draft of the ground rules (step 0) and the basic line of every industry with its gates (step 1). Nothing here is built yet: edit freely, and the game will be built from what you settle on.
A4: How to edit | B4: Yellow cells are yours: your call on each rule, and your notes. Blue numbers are levers (knowledge costs, rates, counts, months): change them and the budget checks update.
A5: Tabs | B5: 0 Ground rules: what each currency is for and the limits every design follows. 0 Stages: the five ranks, how long each should last and what the player does in it. 0 Knowledge: where knowledge comes from at each stage, and the budget it gives. 1 Basic lines: every industry's default chain, each unlock with its rank, knowledge cost and condition. 1 Budget check: do each stage's unlocks fit its knowledge budget? 1 Goods coverage: every good, where it comes from after step 1, and what uses it today. Questions: decisions I need from you before building.
A6: Gate notation | B6: Rank = the town size it waits for (a floor, never the whole gate). Knowledge = what it costs to learn, spent like prestige. Condition = learn by doing: produced so many of a good in total, or a building owned.
A7: Not in this pass | B7: Civic buildings, housing needs (step 2); mixed and late goods such as stained glass, fine clothes, books, arms, wine and jewellery (step 3); extensions, upgrades and choices (step 4); manor, great works, charters (steps 5 and 6). They appear here only where a basic line leads into them.

Sheet Decisions
A1: Settled, and carried into later steps
A2: Your answers to my doubts after the first pass, and what each later step must pick up.
A4: # | B4: Doubt | C4: Settled | D4: Picked up in
A5: 1 | B5: Rank or knowledge? | C5: Either, never both: a few gateway buildings by rank, the rest by knowledge with no rank floor. A town that rushes the glassworks imports sand until it is a Town. | D5: Done (G1, G6)
A6: 2 | B6: Knowledge pace vs essentials | C6: Timber House no longer needs drink: it needs a wooden church, water and two food groups, so its knowledge essentials fit the Hamlet's year. Townhouse checked again once its needs are set. | D6: Step 2
A7: 3 | B7: Fuel | C7: Per batch; firewood 1 unit, charcoal 2; glassworks needs charcoal; homes burn firewood only. | D7: Done (G18)
A8: 4 | B8: The Cooper's condition | C8: Kept as the one exception. | D8: Done (G7)
A9: 5 | B9: Taxes and early coins | C9: Building a manor becomes pressing. The settlers bring tools for two years of a regular set of simple buildings (about 11 tools at the new upkeep rates: see 2 Upkeep). | D9: Step 2 (manor, tax offices)
A10: 6 | B10: First crop | C10: Vegetables (turnips, cabbages, beans) instead of potatoes; the existing good. | D10: Done
A11: 7 | B11: Herbs as weak medicine | C11: Yes: herbs run out three times as fast as medicine. Fine-tune later. | D11: Step 2
A12: 8 | B12: Beekeeper and hives | C12: Both: the beekeeper produces, homemade hives are a small passive. | D12: Done
A13: 9 | B13: Timber House needs | C13: Neither clothes nor drink. Cider no longer marked. | D13: Step 2
A14: 10 | B14: Paper | C14: A Paper Mill (flax, by water) for everyone; the Scriptorium makes books only. Administrative buildings should have options to be fed; failing that, they work worse without paper. | D14: Step 2
A15: 11 | B15: Schools | C15: A public school or a Sunday school (church extension). If both: the public school gives a fixed trickle and slows all work 1-2%; the Sunday school slows work 2-3% but gives knowledge in proportion to the homes it serves. | D15: Steps 2 and 4
A17: Ideas for feeding administrative buildings (to discuss in step 2)
B18: Tally sticks | C18: Notched sticks from the carpenter: cheap and early, but an office on tally sticks handles fewer households.
B19: Wax tablets | C19: From beekeepers' wax: reusable, so used slowly; ties the beekeeper into the town's running.
B20: Parchment | C20: From hides at a parchmenter: dear, but it gives hides a third use.
B21: Paper | C21: From the Paper Mill: the best, full efficiency.
A23: Step 2, round 2
B24: Scale | C24: Only timber and coin costs come down; production, food, storage, taxes and prices stay; rebalance at the end (G19). Costs stay flat across tiers, finer materials instead (G21). Simple buildings wear at most a tool a year (2 Upkeep).
B25: Fine pottery | C25: A luxury only.
B26: Luxuries | C26: Jewellery, fine clothes, glass, wine, fine pottery. Books and mead are not luxuries.
B27: Garments | C27: Clothes or boots for the Townhouse; both for the Merchant's House.
B28: Bathhouse | C28: Opens at Borough.
B29: Builder's Yard | C29: Waits for a Draught Stable (exception to G7).
B30: Market, Alehouse, Courthouse, church, armoury, potter | C30: As I read them: by crew; policing past Borough; one church per town; armoury to the manor (step 5); potter uses dye.
A32: Costs edit and step 3
B33: Production speed | C33: Most non-food goods slow down to match the cheaper buildings; provisionally a third of today's speed (your costs are a third of today's on the median). To watch: your new upkeep is higher than today's for most workshops, so tools could get scarce. Settled in step 8.
B34: Home sizes | C34: Residents no longer grow much with the home's level: Townhouse, Merchant's and Patrician houses all hold 9, so a big town has more homes, and markets and alehouses serve by crew.
B35: Manor grounds | C35: Every manor building must touch the manor or a manor decoration that touches it; the manor's grounds blend into one dirt shape (art). Step 5.
B36: Watch towers | C36: At most 2 for each rank above Village. Step 5.
B37: Roads and orchards | C37: Stone road 2 stone a tile, cobbles 2 dressed stone a tile, orchards keep 2 coins a tile.
B38: Step 3 | C38: All agreed: Embroiderer and Glazier, parchment, mead for all, watch wears clothes and boots, medicine for sickness, jeweller sets silver with glass, books bought or charter. Silver to watch closely. Monasteries only consume books (no copying extension).
A40: Step 4
B41: Extensions | C41: A workplace may have several different extensions, each built once; they add an ability and may add a flat bonus.
B42: Upgrades | C42: Usually places and another bonus together; chains are possible (the stores already have one: loft, then improved).
B43: Learning by doing | C43: Required for upgrades and extensions, optional for variants and choices.
B44: Your additions | C44: Large woodcutter's lodge, ox tool-shed, water sawmill as a building, roads behind knowledge, cattle breeds as a choice, animal sheds, pears and strawberries, fish pond, trade choices, goods cart, trade centre, huge ships, expanded draught stable, mounted guard, improved stores, ox-carts.
B45: Dropped | C45: Roofs and heraldic banners are no longer in the table (5 Questions asks whether on purpose).
...

Sheet 0 Ground rules
A1: Step 0: ground rules
A2: Every later step is checked against these. Mark each one Agree / Change / Drop in the yellow column.
A4: ID | B4: Area | C4: Rule | D4: Why | E4: Your call | F4: Your notes | G4: Status
A5: Currencies
A6: G1 | B6: Town rank | C6: Town rank decides how big the town may grow: house levels, manor levels, Great Works and decorations. A few gateway buildings unlock by rank alone (Farmstead: Hamlet; Clay Pit and Bloomery: Village; Sand Pit: Town). | D6: Rank already drives houses and the manor; keeping it to "size" stops it competing with knowledge. | E6: Change | F6: Basic industries buildings will be unlocked by rank alone | G6: Revised to your note
A7: G2 | B7: Knowledge | C7: Knowledge decides what your people know how to build: every building outside the starting set, extra recipes, crops, animals, workplace extensions and upgrades. It is spent, like prestige. | D7: Spending makes each unlock a choice; a threshold would just open everything in order. | E7: Agree | G7: As agreed
A8: G3 | B8: Prestige | C8: Prestige is the lord's: charters, titles, feasts and fairs, works of art, the retinue. It never unlocks ordinary industry. | D8: Players always know which currency they need. | E8: Agree | G8: As agreed
A9: G4 | B9: Charters | C9: Charters are the town's specialisation: exclusive choices, guild buildings and strong bonuses. A charter building may offer another way to meet a need, but never the only way. | D9: No town is locked out of a house level by the path it chose. | E9: Agree | G9: As agreed
A10: G5 | B10: Coins | C10: Coins run the economy and are never a gate. Taxes are collected only once there is a manor; the manor taxes up to the first 45 villagers (a Town's worth), and beyond that tax offices must be built (step 2). | E10: Change | F10: Let's add taxation system. Taxas can only be collected once a manor is built, the mannor can collect taxes from up to the population necessary to reach town, then tax offices must be built | G10: Revised to your note
A11: Gates
A12: G6 | B12: Shape | C12: Every unlock has either a rank or a knowledge cost, never both. Knowledge unlocks have no rank floor: their price is what makes them feasible or not. | D12: One readable line per unlock: "Town · 8 knowledge · after 40 ore". | E12: Change | F12: Let's not use rank for knowledge unlocks, the knowloedge price will somewhat define what is feasible for unlocking. | G12: Revised to your note
A13: G7 | B13: Conditions | C13: Conditions (learning by doing) are only for choices, extensions, some decorations and special buildings, never for production buildings. Exception: the Cooper waits for a trading post, dock or winery, since crates are useless without trade. | D13: Gives the "you learn by doing" feel without a second experience currency. | E13: Change | F13: We will drop conditions like this from all production buildings and leave only for choices, extensions and later some decorations and special buildings | G13: Revised to your note
A14: G8 | B14: Cost bands | C14: Knowledge prices: the basic building that reaches the end of a production line is cheap; extensions, choices and more efficient buildings cost in proportion to their bonus. | D14: Basic industry should not be hard to unlock; knowledge becomes the real constraint from Town on. | E14: Change | F14: I agree with the why. Basic building to get to the end of production line will be cheap, extensions, choices and more efficient buildings are more expensive proportionally to the bonus | G14: Revised to your note
A15: G9 | B15: Budgets | C15: What the next house level needs must fit inside a stage's basic budget with room to spare. Optional lines may add up to more than the budget, so the player chooses what to learn first. | D15: Nobody stalls on a house level; there is still a choice. | E15: Agree | G15: As agreed
A16: G10 | B16: Starting set | C16: Free from the start: Cottage, Woodcutter (timber and firewood), Sawmill, Quarry, Forager (berries), Hunter, Fisher, Storehouse, Granary, Well, Market, and the vegetable patch and hen coop in backyards. Mushrooms stop being a good (they stay on the map). | D16: Enough to survive the first winter; everything else is learned. | E16: Change | F16: Maybe not fit here, but since we will already have lot's of good types, we don't need mushrooms anymore and they were hard to spot anyway. Let's keep the visual mushrooms but they don't count towards food distribution rules nor are good anymore | G16: Revised to your note
A17: G11 | B17: Data | C17: Every gate lives in one table (this workbook's 1 Basic lines, later more) that the game reads. | D17: You can rebalance in the sheet. | E17: Agree | G17: As agreed
A18: Goods and buildings
A19: G12 | B19: Build costs | C19: At most 4 materials plus coins in any build or upgrade cost. | D19: New materials replace old ones rather than lengthen lists. | E19: Agree | G19: As agreed
A20: G13 | B20: Recipes | C20: At most 3 inputs per recipe. | E20: Agree | G20: As agreed
A21: G14 | B21: Every good | C21: Every good has a source by the stage it is needed (made, or bought as a stopgap) and a use. Foods count as used by being eaten. Intermediate goods (flour, hides, woad) need only the chain they feed. Finished goods need two uses: a recipe, a build cost, upkeep, a home need, a luxury or tavern drink; a luxury may count export as one. | D21: No dead ends, and no goods that only exist to be sold (oats today). | E21: Agree | G21: As agreed
A22: G15 | B22: Upkeep | C22: Simple buildings wear tools or wood parts at low rates from the start; if the town is slow to make them, it imports them. The settlers bring enough tools for two years of a regular set of simple buildings. | D22: Today woodcutters, quarries and farms wear tools that cannot be made before a Town. | E22: Change | F22: Simple buildings consume at lower rates, yes, but they can consume tools or parts, if the player is too slow in developing the industry, they must be imported. | G22: Revised to your note
A23: G16 | B23: One craft | C23: A building does one craft. Several recipes only where they share the workplace and skill (tailor: clothes and boots). Fine clothes get their own building. | D23: Keeps the build menu readable. | E23: Change | F23: Fine clothes will have their own building | G23: Revised to your note
A24: G17 | B24: Pace | C24: Each rank opens at most three new lines (a line = a new raw good and what it becomes). | D24: One thing to learn at a time. | E24: Agree | G24: As agreed
A25: G18 | B25: Fuel | C25: Workshops with a fire burn fuel with each batch, like an input, so an idle workshop burns nothing. One firewood is one unit of fuel and one charcoal two. Fuel burners: bakery, brewhouse, kiln, potter, lime kiln, bloomery, blacksmith, dyer. The glassworks needs charcoal itself, for the heat. Homes heat with firewood only. | D25: Your answer to doubt 3: always fuel, charcoal just more efficient. | E25: Agree | G25: New, from your answers
A26: G19 | B26: Scale | C26: Construction costs are as in 2 Costs (about a third of today's material on the median). To match, most non-food goods are made more slowly (provisionally a third of today's speed). Food production, storage, taxes and prices wait for the rebalance (step 8). | D26: Your answer: reduce the production speed of most goods; food waits for step 8. | G26: Revised to your note
A27: G20 | B27: Crew | C27: Everything a building does scales with how many of its places are filled: output, upkeep, and also services (how many homes an alehouse or market serves, how much a trading post moves, how fast haulers fetch, how much a builder's yard speeds, how much a monastery or university teaches). | D27: Today output and upkeep scale with the crew, but most services work at full strength with a single worker. | G27: New, from your note
A28: G21 | B28: Costs | C28: A building costs roughly the same number of units whatever its tier (about 3-12; Great Works more). Higher tiers ask for finer materials, or more of a simpler one, not ever bigger piles. | D28: Your balance reference. | E28: Agree | G28: New, from your note

Sheet 0 Knowledge
A1: Step 0: where knowledge comes from
A2: Typical count = how many a town has on average during that stage (blue, edit them). The totals feed 0 Stages.
A4: Source | B4: From rank | C4: Knowledge a month each | D4: Hamlet (count) | E4: Village (count) | F4: Town (count) | G4: Borough (count) | H4: City (count) | I4: Change from today
A5: Elders' lore (camp, then manor hall) | B5: Hamlet | C5: 0.1 | D5: 1 | E5: 1 | F5: 1 | G5: 1 | H5: 1 | I5: New: a trickle from the first day, so the Hamlet can learn.
A6: Wooden church | B6: Village | C6: 0.25 | D6: 0 | E6: 1 | F6: 0 | G6: 0 | H6: 0 | I6: Moves from Town to Village (step 2 to confirm).
A7: Stone Church | B7: Town | C7: 1 | D7: 0 | E7: 0 | F7: 1 | G7: 1 | H7: 2
A8: Timber House (lived in) | B8: Village | C8: 0.05 | D8: 0 | E8: 10 | F8: 12 | G8: 15 | H8: 20 | I8: New: a little learning in every Timber House.
A9: Townhouse (lived in) | B9: Town | C9: 0.1 | D9: 0 | E9: 0 | F9: 6 | G9: 15 | H9: 20
A10: Merchant's House (lived in) | B10: Borough | C10: 0.25 | D10: 0 | E10: 0 | F10: 0 | G10: 6 | H10: 20
A11: Monastery (with its book) | B11: Town | C11: 3 | D11: 0 | E11: 0 | F11: 0.5 | G11: 1 | H11: 1
A12: Scriptorium at work (charter) | B12: Town | C12: 1 | D12: 0 | E12: 0 | F12: 0 | G12: 0.5 | H12: 1
A13: University (with its books) | B13: Borough | C13: 10 | D13: 0 | E13: 0 | F13: 0 | G13: 0.3 | H13: 1
A14: Public school (or a Sunday school extension) | B14: Town | C14: 0.25 | D14: 0 | E14: 0 | F14: 1 | G14: 1 | H14: 1 | I14: New: slightly decrease efficiency (1 to 2% maybe)
A15: Cathedral | B15: Borough | C15: 3 | D15: 0 | E15: 0 | F15: 0 | G15: 0.2 | H15: 1
A16: Knowledge a month (average in stage) | D16: =SUMPRODUCT($C$5:$C$15,D5:D15) | E16: =SUMPRODUCT($C$5:$C$15,E5:E15) | F16: =SUMPRODUCT($C$5:$C$15,F5:F15) | G16: =SUMPRODUCT($C$5:$C$15,G5:G15) | H16: =SUMPRODUCT($C$5:$C$15,H5:H15)

Sheet 0 Stages
A1: Step 0: the stages of a game
A2: Months in stage and basic share are levers (blue). One month = 10 days.
A4: Rank | B4: Population from | C4: Months in stage | D4: Player focus | E4: Home level reached | F4: New lines (step 1) | G4: Knowledge a month | H4: Knowledge in stage | I4: Basic share | J4: Basic budget
A5: Hamlet | B5: 0 | C5: 12 | D5: Survive the first winter: food, firewood, shelter, somewhere to store it. Fell, quarry, gather, hunt, fish; the first fields. Trade possible. | E5: Cottage | F5: Timber (planks), first fields | G5: ='0 Knowledge'!D16 | H5: =C5*G5 | I5: 1 | J5: =H5*I5
A6: Village | B6: 20 | C6: 24 | D6: The first processing chains: bread, ale, cloth and clothes, tiles, animals, orchards. First trade. The church. Some second-tier chains | E6: Timber House | F6: Bread, ale and cider, cloth and leather, clay and tiles, herds, orchards | G6: ='0 Knowledge'!E16 | H6: =C6*G6 | I6: 0.7 | J6: =H6*I6
A7: Town | B7: 45 | C7: 36 | D7: First luxury, finish essential second-tier, begin specialization. The first charter. | E7: Townhouse | F7: Iron and tools, dressed stone and mortar, dyes, medicine, pottery | G7: ='0 Knowledge'!F16 | H7: =C7*G7 | I7: 0.5 | J7: =H7*I7
A8: Borough | B8: 90 | C8: 48 | D8: Luxuries and mixed goods: glass, fine clothes, books, arms. Great works begin. | E8: Merchant's House | F8: Glass | G8: ='0 Knowledge'!G16 | H8: =C8*G8 | I8: 0.15 | J8: =H8*I8
A9: City | B9: 150 | C9: 60 | D9: Great works, renown, refining the town: extensions, upgrades, choices. | E9: Merchant's House | F9: (extensions and choices, step 4) | G9: ='0 Knowledge'!H16 | H9: =C9*G9 | I9: 0 | J9: =H9*I9
A11: Basic share: how much of a stage's knowledge the basic lines may take; the rest is for mixed goods, extensions and choices (steps 3 and 4). Early stages are almost all basic industry.

Sheet 1 Basic lines
A1: Step 1: the basic line of every industry, and its gates
A2: Edit rank, knowledge and condition freely. "Essential" = needed for that stage's home level (see 1 Budget check).
A4: Line | B4: # | C4: Unlock | D4: Kind | E4: Makes | F4: From | G4: Rank | H4: Knowledge | I4: Condition (learn by doing) | J4: Upkeep (G15) | K4: Essential for | L4: Why this gate | M4: Change from today | N4: Your notes
A5: Timber | B5: 1 | C5: Woodcutter | D5: Building | E5: timber, firewood | G5: start | J5: Tools | L5: Start: the first thing every town needs. | M5: Wears wood parts from Village (today tools).
A6: Timber | B6: 2 | C6: Forester | D6: Building | E6: new trees | H6: 1 | J6: none | L6: Teaches replanting once the first woods thin. | M6: Was open from the start.
A7: Timber | B7: 3 | C7: Sawmill | D7: Building | E7: planks | F7: timber | G7: start | J7: Tools | K7: Timber House | L7: Timber Houses need planks the moment the town is a Village. | M7: Was Village.
A8: Timber | B8: 4 | C8: Carpenter | D8: Building | E8: wood parts | F8: planks | H8: 1 | J8: tools* | K8: Timber House | L8: Village buildings wear wood parts; mills are built with them. | M8: *wears tools only from Town on.
A9: Timber | B9: 5 | C9: Cooper | D9: Building | E9: crates | F9: planks, iron | H9: 3 | I9: a trading post built or dock or winery unlocked | J9: wood parts | L9: Crates matter once there is trade. | M9: Condition kept as an exception to G7: crates are useless without trade.
A10: Stone & earth | B10: 1 | C10: Quarry | D10: Building | E10: stone | G10: start | J10: Tools | L10: Start. | M10: Wears wood parts from Village (today tools).
A11: Stone & earth | B11: 2 | C11: Clay Pit | D11: Building | E11: clay | G11: Village | J11: wood parts | K11: Townhouse | L11: Needs a shore; the first earth line.
A12: Stone & earth | B12: 3 | C12: Kiln | D12: Building | E12: tiles | F12: clay + fuel | H12: 1 | J12: wood parts | K12: Townhouse | L12: Townhouses are roofed with tiles.
A13: Stone & earth | B13: 4 | C13: Stonemason | D13: Building | E13: dressed stone | F13: stone | H13: 2 | J13: tools | K13: Merchant's House | L13: Merchant's Houses, the stone manor and walls use dressed stone. | M13: Was Village.
A14: Stone & earth | B14: 5 | C14: Sand Pit | D14: Building | E14: sand | G14: Town | J14: tools | L14: Needs a shore; competes with the clay pit for it. | M14: Was Village.
A15: Stone & earth | B15: 6 | C15: Lime Kiln | D15: Building | E15: mortar | F15: stone, sand + fuel | H15: 2 | J15: tools | K15: Merchant's House | L15: Mortar joins dressed stone in the fine buildings (uses set in step 3). | M15: Was Village.
A16: Stone & earth | B16: 7 | C16: Potter | D16: Building | E16: fine pottery | F16: clay + fuel + dye | H16: 6 | J16: wood parts | K16: Merchant's House | L16: The finest homes want glazed pottery.
A17: Grain & bread | B17: 1 | C17: Farmstead + vegetables | D17: Building | E17: vegetables (turnips, cabbages, beans) | G17: Hamlet | J17: none | K17: Timber House | L17: The first food that is grown, not gathered. | M17: New easy first crop instead of wheat: eaten without milling, poor yield, feeds less. Reuses the vegetables good. Was Village with wheat. | N17: Potatos or generic vegetables can replace wheat as initial agriculture, since they need no forther work, giving unlucky players a way out (potatos must be inefficient to grow and to feed to counter the easy access)
A18: Grain & bread | B18: 2 | C18: Windmill + Wheat | D18: Building | E18: grain + flour | F18: grain | H18: 1 | J18: wood parts | M18: Wheat comes with the windmill.
A19: Grain & bread | B19: 3 | C19: Bakery | D19: Building | E19: bread | F19: flour + fuel | H19: 1 | J19: wood parts
A20: Grain & bread | B20: 4 | C20: Watermill | D20: Building | E20: flour | F20: grain | H20: 5 | J20: wood parts | L20: The bigger mill, for towns on a river.
A21: Grain & bread | B21: 5 | C21: Barley | D21: Crop | E21: barley | H21: 1 | K21: Townhouse
A22: Grain & bread | B22: 6 | C22: Brewhouse: ale | D22: Building | E22: ale | F22: barley + fuel | H22: 1 | J22: wood parts | K22: Townhouse | L22: Timber Houses want an alehouse with drink. | M22: Whichever drink is learned first unlocks the brewhouse with it; the other is a recipe. | N22: Whickever brewhouse picked first unlock the building and the obter unlock recipes
A23: Herds | B23: 1 | C23: Animal farm: sheep and pigs | D23: Building | E23: wool, pork, hides | H23: 2 | L23: Wool is the other way to cloth.
A24: Herds | B24: 2 | C24: Cattle | D24: Animal | E24: milk, meat, hides | H24: 2 | L24: The bigger, dearer beast. | M24: Was open with the animal farm.
A25: Herds | B25: 3 | C25: Dairy | D25: Building | E25: cheese | F25: milk | H25: 2 | J25: wood parts
A26: Orchards & hives | B26: 1 | C26: Orchard keeper: apples | D26: Building | E26: apples | H26: 1 | J26: wood parts
A27: Orchards & hives | B27: 2 | C27: Plums | D27: Crop | E27: plums | H27: 1 | L27: More fruit, more variety. | M27: Pears move to step 4 (a slow, rich variant).
A28: Orchards & hives | B28: 3 | C28: Brewhouse: cider | D28: Recipe | E28: cider | F28: apples + fuel | H28: 1 | L28: The other drink, for towns with orchards rather than barley.
A29: Orchards & hives | B29: 4 | C29: Beehives (backyard) | D29: Backyard | E29: honey | H29: 2 | L29: Bees follow the blossom.
A30: Orchards & hives | B30: 5 | C30: Beekeeper | D30: Building | E30: honey | H30: 2 | L30: The real honey producer; backyard hives stay as a small homemade extra. | M30: New building. | N30: New building
A31: Wild food & herbs | B31: 1 | C31: Forager, Hunter, Fisher | D31: Building | E31: berries, meat, fish | H31: 0 | J31: none | L31: Start. | M31: Mushrooms stop being a good; they stay on the map as decoration.
A32: Wild food & herbs | B32: 2 | C32: Forager: herbs | D32: Recipe | E32: herbs | H32: 1 | K32: Townhouse | L32: Herbs wait until the forager knows the woods. | M32: Was open from the start. Homes without medicine may use herbs instead, but herbs run out three times as fast. | N32: Herbs can serve as medicine, with dratically smaller efficiency
A33: Wild food & herbs | B33: 3 | C33: Apothecary | D33: Building | E33: medicine | F33: herbs | H33: 4 | J33: tools | K33: Townhouse | L33: Townhouses want medicine.
A34: Cloth & leather | B34: 1 | C34: Flax | D34: Crop | E34: flax | H34: 1 | K34: Townhouse | L34: Linen without sheep.
A35: Cloth & leather | B35: 2 | C35: Weaver | D35: Building | E35: cloth | F35: wool or flax | H35: 2 | J35: wood parts | K35: Townhouse
A36: Cloth & leather | B36: 3 | C36: Tailor: clothes | D36: Building | E36: clothes | F36: cloth | H36: 2 | J36: wood parts | K36: Townhouse | L36: Timber Houses need clothes.
A37: Cloth & leather | B37: 4 | C37: Tanner | D37: Building | E37: leather | F37: hides | H37: 2 | J37: wood parts | K37: Merchant's House
A38: Cloth & leather | B38: 5 | C38: Tailor: boots | D38: Recipe | E38: boots | F38: leather | H38: 3 | K38: Merchant's House | L38: Townhouses need boots. | M38: Was open with the tailor. Boots are now a Merchant's House need (step 2).
A39: Cloth & leather | B39: 6 | C39: Woad | D39: Crop | E39: woad | H39: 3 | L39: The dye line arrives with the Town.
A40: Cloth & leather | B40: 7 | C40: Dyer | D40: Building | E40: dyes | F40: woad or berries + fuel | H40: 5 | J40: wood parts | L40: Dyes feed fine clothes and stained glass (step 3). | M40: Berries are a second, food-hungry route to dyes. | N40: Adding berries give another route to dyies that consume a type of food that is limited
A41: Iron & tools | B41: 1 | C41: Bog Iron Pit | D41: Building | E41: ore | H41: 4 | J41: tools | L41: Needs bog ore on the map.
...

Sheet 1 Budget check
A1: Steps 1-2: can each home level's essentials be learned by the time it opens?
A2: Counts the basic lines, civic buildings and step 3. Rank-gated, charter or free unlocks cost no knowledge (G6).
A4: Needed for | B4: Opens at | C4: Essential unlocks | D4: Knowledge for them | E4: Knowledge earned before it opens | F4: Fits? | G4: Spare
A5: Timber House | B5: Village | C5: =COUNTIF('1 Basic lines'!$K$5:$K$46,A5)+COUNTIF('2 Civic'!$I$5:$I$30,A5)+COUNTIF('3 Mixed & late'!$I$5:$I$12,A5) | D5: =SUMIF('1 Basic lines'!$K$5:$K$46,A5,'1 Basic lines'!$H$5:$H$46)+SUMIF('2 Civic'!$I$5:$I$30,A5,'2 Civic'!$E$5:$E$30)+SUMIF('3 Mixed & late'!$I$5:$I$12,A5,'3 Mixed & late'!$G$5:$G$12) | E5: ='0 Stages'!H5 | F5: =IF(D5<=E5,"Yes","No") | G5: =E5-D5
A6: Townhouse | B6: Town | C6: =COUNTIF('1 Basic lines'!$K$5:$K$46,A6)+COUNTIF('2 Civic'!$I$5:$I$30,A6)+COUNTIF('3 Mixed & late'!$I$5:$I$12,A6) | D6: =SUMIF('1 Basic lines'!$K$5:$K$46,A6,'1 Basic lines'!$H$5:$H$46)+SUMIF('2 Civic'!$I$5:$I$30,A6,'2 Civic'!$E$5:$E$30)+SUMIF('3 Mixed & late'!$I$5:$I$12,A6,'3 Mixed & late'!$G$5:$G$12) | E6: ='0 Stages'!H5+'0 Stages'!H6 | F6: =IF(D6<=E6,"Yes","No") | G6: =E6-D6
A7: Administrative buildings | B7: Town | C7: =COUNTIF('1 Basic lines'!$K$5:$K$46,A7)+COUNTIF('2 Civic'!$I$5:$I$30,A7)+COUNTIF('3 Mixed & late'!$I$5:$I$12,A7) | D7: =SUMIF('1 Basic lines'!$K$5:$K$46,A7,'1 Basic lines'!$H$5:$H$46)+SUMIF('2 Civic'!$I$5:$I$30,A7,'2 Civic'!$E$5:$E$30)+SUMIF('3 Mixed & late'!$I$5:$I$12,A7,'3 Mixed & late'!$G$5:$G$12) | E7: ='0 Stages'!H5+'0 Stages'!H6 | F7: =IF(D7<=E7,"Yes","No") | G7: =E7-D7
A8: Merchant's House | B8: Borough | C8: =COUNTIF('1 Basic lines'!$K$5:$K$46,A8)+COUNTIF('2 Civic'!$I$5:$I$30,A8)+COUNTIF('3 Mixed & late'!$I$5:$I$12,A8) | D8: =SUMIF('1 Basic lines'!$K$5:$K$46,A8,'1 Basic lines'!$H$5:$H$46)+SUMIF('2 Civic'!$I$5:$I$30,A8,'2 Civic'!$E$5:$E$30)+SUMIF('3 Mixed & late'!$I$5:$I$12,A8,'3 Mixed & late'!$G$5:$G$12) | E8: ='0 Stages'!H5+'0 Stages'!H6+'0 Stages'!H7 | F8: =IF(D8<=E8,"Yes","No") | G8: =E8-D8
A9: Patrician House | B9: City | C9: =COUNTIF('3 Mixed & late'!$I$5:$I$12,A9) | D9: =SUMIF('3 Mixed & late'!$I$5:$I$12,A9,'3 Mixed & late'!$G$5:$G$12) | E9: ='0 Stages'!H5+'0 Stages'!H6+'0 Stages'!H7+'0 Stages'!H8 | F9: =IF(D9<=E9,"Yes","No") | G9: =E9-D9
A10: Every unlock in steps 1-3 | B10: end of Town | C10: =COUNT('1 Basic lines'!$H$5:$H$46)+COUNT('2 Civic'!$E$5:$E$30)+COUNT('3 Mixed & late'!$G$5:$G$12) | D10: =SUM('1 Basic lines'!$H$5:$H$46)+SUM('2 Civic'!$E$5:$E$30)+SUM('3 Mixed & late'!$G$5:$G$12) | E10: ='0 Stages'!H5+'0 Stages'!H6+'0 Stages'!H7 | F10: =IF(D10<=E10,"Yes","No") | G10: =E10-D10
A12: Timber House: a wooden church (Village rank), a well (free) and two food groups, so only what column K marks costs knowledge.
A13: Townhouse: boots moved up and tools can be imported, so the iron line is no longer essential for it.

Sheet 1 Goods coverage
A1: Step 1: every good, its source after step 1, and its uses today
A2: Uses are read from the game as it is now. "Needs" flags goods with fewer than two uses (G14).
A4: Good | B4: Group | C4: Source after step 1 | D4: From rank | E4: Uses today | F4: Use count | G4: Status (G14) | H4: Your notes
A5: Timber | B5: materials | C5: Woodcutter | D5: start | E5: builds Burgage House; builds Woodcutter's Lodge; builds Forester's Hut; builds Stone Quarry; builds Bog Iron Pit; builds Clay Pit; builds Sand Pit; builds Forager's Hut; builds Hunting Camp; builds Fisher's Hut; builds Farmstead; builds Animal Farm; builds Orchard Keeper's Lodge; builds Windmill; builds Watermill; builds Bakery; builds Brewhouse; builds Dairy; builds Sawpit; Sawpit; builds Charcoal Burner; Charcoal Burner; builds Tannery; builds Weaver; builds Dyer's Workshop; builds Tailor & Cobbler; builds Carpenter's Workshop; builds Cooper's Workshop; builds Potter's Workshop; builds Stonemason's Yard; builds Lime Kiln; builds Tile Kiln; builds Bloomery; Blacksmith; builds Well; builds Storehouse; builds Granary; builds Silo; builds Trading Post; builds Dock; builds Draught Stable; builds Builder's Yard; builds Alehouse; builds Apothecary; builds Church; builds Flower Garden; builds Wayside Shrine; builds Public Garden; builds Maypole; builds Manor; builds Lord's Stable; upgrade to Timber House; Manor House | F5: 53 | G5: OK
A6: Firewood | B6: materials | C6: Woodcutter | D6: start | E6: Dyer's Workshop; Potter's Workshop; Lime Kiln; Tile Kiln; Bloomery | F6: 5 | G6: OK
A7: Planks | B7: materials | C7: Sawmill | D7: Hamlet | E7: builds Bog Iron Pit; builds Animal Farm; builds Orchard Keeper's Lodge; builds Brewhouse; builds Winery; builds Weaver; builds Dyer's Workshop; builds Tailor & Cobbler; builds Carpenter's Workshop; Carpenter's Workshop; builds Cooper's Workshop; Cooper's Workshop; builds Glassworks; builds Blacksmith; builds Armoury; Armoury; Armoury (bows); builds Jeweller's Shop; builds Trading Post; builds Dock; builds Draught Stable; builds Builder's Yard; builds Alehouse; builds Apothecary; builds Scriptorium; builds Church; builds Monastery; builds Manor; builds Lord's Stable; builds Watch Tower; builds Manor Garden; builds Bell Tower; builds Covered Market Hall; builds Cathedral; builds University; builds Guildhall; upgrade to Timber House; upgrade to Townhouse; upgrade to Merchant's House; Stone Manor | F7: 40 | G7: OK
A8: Wood Parts | B8: materials | C8: Carpenter | D8: Village | E8: builds Windmill; builds Watermill; builds Winery; upkeep | F8: 4 | G8: OK
A9: Stone | B9: materials | C9: Quarry | D9: start | E9: builds Watermill; builds Bakery; builds Winery; builds Potter's Workshop; builds Stonemason's Yard; Stonemason's Yard; builds Lime Kiln; Lime Kiln; builds Glassworks; builds Tile Kiln; builds Bloomery; builds Blacksmith; builds Armoury; builds Silo; builds Dock; builds Builder's Yard; builds Monastery; builds Wayside Shrine; builds Stone Fountain; builds Public Garden; builds Manor; builds Watch Tower; builds Town Wall; builds Manor Garden; builds Bell Tower; builds Cathedral; upgrade to Townhouse; Manor House; Stone Manor | F9: 29 | G9: OK
A10: Dressed Stone | B10: materials | C10: Stonemason | D10: Town | E10: builds Jeweller's Shop; builds Scriptorium; builds Town Wall; builds Lord's Statue; builds Bell Tower; builds Covered Market Hall; builds Cathedral; builds University; builds Guildhall; upgrade to Merchant's House; Stone Manor | F10: 11 | G10: OK
A11: Clay | B11: materials | C11: Clay Pit | D11: Village | E11: Potter's Workshop; Tile Kiln | F11: 2 | G11: OK
A12: Roof Tiles | B12: materials | C12: Kiln | D12: Village | E12: builds Monastery; builds Covered Market Hall; builds Cathedral; builds University; builds Guildhall; upgrade to Townhouse; upgrade to Merchant's House | F12: 7 | G12: OK
A13: Bog Iron | B13: materials | C13: Bog Iron Pit | D13: Town | E13: Bloomery | F13: 1 | G13: OK: feeds one chain
A14: Iron | B14: materials | C14: Bloomery | D14: Town | E14: Blacksmith; Armoury (armour) | F14: 2 | G14: OK
A15: Silver | B15: materials | C15: step 3: no source but a charter today | E15: Jeweller's Shop | F15: 1 | G15: OK: feeds one chain
A16: Crates | B16: materials | C16: Cooper | D16: Village | E16: Winery; trade carts | F16: 2 | G16: OK
A17: Sand | B17: materials | C17: Sand Pit | D17: Town | E17: Lime Kiln; Glassworks; Glassworks (glass) | F17: 3 | G17: OK
A18: Mortar | B18: materials | C18: Lime Kiln | D18: Town | F18: 0 | G18: No use yet: step 3
A19: Charcoal | B19: materials | C19: Charcoal Burner | D19: Town | E19: Glassworks; Glassworks (glass) | F19: 2 | G19: OK
A20: Glass | B20: materials | C20: Glassworks | D20: Borough | E20: Glassworks (stained glass) | F20: 1 | G20: OK: feeds one chain
A21: Stained Glass | B21: materials | C21: step 3: Glassworks recipe | E21: cathedral windows (commission) | F21: 1 | G21: OK: feeds one chain
A22: Bread | B22: food | C22: Bakery | D22: Village | E22: food | F22: 1 | G22: OK: food
A23: Meat | B23: food | C23: Forager, Hunter, Fisher | D23: start | E23: food | F23: 1 | G23: OK: food
A24: Pork | B24: food | C24: Animal farm: sheep and pigs | D24: Village | E24: food | F24: 1 | G24: OK: food
A25: Fish | B25: food | C25: Forager, Hunter, Fisher | D25: start | E25: food | F25: 1 | G25: OK: food
A26: Eggs | B26: food | C26: Hen coop (backyard) | D26: start | E26: food | F26: 1 | G26: OK: food
A27: Berries | B27: food | C27: Forager, Hunter, Fisher | D27: start | E27: food | F27: 1 | G27: OK: food
A28: Mushrooms | B28: food | C28: Forager, Hunter, Fisher | D28: start | E28: food | F28: 1 | G28: OK: food
A29: Vegetables | B29: food | C29: Vegetable patch (backyard) | D29: start | E29: food | F29: 1 | G29: OK: food
A30: Apples | B30: food | C30: Orchard keeper: apples | D30: Village | E30: Brewhouse (cider); food | F30: 2 | G30: OK: food
A31: Pears | B31: food | C31: Pears and plums | D31: Village | E31: food | F31: 1 | G31: OK: food
A32: Plums | B32: food | C32: Pears and plums | D32: Village | E32: food | F32: 1 | G32: OK: food
A33: Grapes | B33: food | C33: charter: vines | E33: Winery; food | F33: 2 | G33: OK: food
A34: Honey | B34: food | C34: Beehives (backyard) | D34: Village | E34: Brewhouse (mead); food | F34: 2 | G34: OK: food
A35: Milk | B35: food | C35: Cattle | D35: Village | E35: Dairy; food | F35: 2 | G35: OK: food
A36: Cheese | B36: food | C36: Dairy | D36: Village | E36: food | F36: 1 | G36: OK: food
A37: Wheat | B37: goods | C37: Farmstead + wheat fields | D37: Hamlet | E37: Windmill; Watermill | F37: 2 | G37: OK
A38: Barley | B38: goods | C38: Barley | D38: Village | E38: Brewhouse; Brewhouse (ale) | F38: 2 | G38: OK
A39: Oats | B39: goods | C39: none (unused) | F39: 0 | G39: Drop (folded into grain long ago)
A40: Flour | B40: goods | C40: Windmill | D40: Village | E40: Bakery | F40: 1 | G40: OK: feeds one chain
A41: Flax | B41: goods | C41: Flax | D41: Village | E41: Weaver (linen); Scriptorium; Scriptorium (paper) | F41: 3 | G41: OK
...

Sheet 2 Housing
A1: Step 2: the housing ladder
A2: What each home level needs and what it gives back. Knowledge per home is linked from 0 Knowledge (green).
A4: Level | B4: Opens at | C4: Holds | D4: Tax × | E4: Upgrade cost | F4: Services nearby | G4: Goods it uses | H4: Food | I4: Knowledge a month | J4: Change from today | K4: Your notes
A5: Cottage | B5: Hamlet | C5: 5 | D5: 1 | E5: 3 timber (to build) | F5: — | G5: — | H5: Enough food; firewood in winter | I5: 0
A6: Timber House | B6: Village | C6: 7 | D6: 1.5 | E6: 3 planks, 2 timber | F6: A wooden church; a well, market stall | G6: — | H6: 2 food groups | I6: ='0 Knowledge'!C8 | J6: No longer needs a market, drink or clothes; now needs a church (your answer).
A7: Townhouse | B7: Town | C7: 9 | D7: 2 | E7: 5 planks, 4 tiles, 3 stone | F7: an alehouse or tavern with drink, a stone church | G7: Clothes or boots (either garment); medicine (herbs will do, used three times as fast) | H7: 3 food groups | I7: ='0 Knowledge'!C9 | J7: Drink and the market move here from the Timber House. Boots move up to the Merchant's House. The church need moves down to the Timber House.
A8: Merchant's House | B8: Borough | C8: 9 | D8: 3 | E8: 3 dressed stone, 5 tiles, 3 mortar, 1 glass, 5 coins | F8: A dressed stone church; a bathhouse (proposal) | G8: Clothes, boots, medicine; one luxury (jewellery, fine clothes, glass, wine or fine pottery) | H8: 4 food groups | I8: ='0 Knowledge'!C10 | J8: Mortar and glass replace planks and tools in the cost: their first real uses (G14). Glassware is a new luxury (your note). Fine pottery is now only a luxury; books and mead are no longer luxuries.
A9: Patrician House (proposal) | B9: City | C9: 9 | D9: 4 | E9: 5 dressed stone, 4 mortar, 1 stained glass, 25 coins | F9: As the Merchant's House, and a school (public or Sunday), a Great Work | G9: As the Merchant's House, plus fine clothes and two more luxury | H9: 4 food groups | I9: 0.75 | J9: New fifth level, so the City has a home to grow into. Your call. | K9: I like it, but I made it even more challeging
A11: Every level also needs everything the level below needs. Homes take goods from the market one at a time as they wear out (one every two months), as today.

Sheet 2 Civic
A1: Step 2: civic buildings, their gates and what they run on
A2: Gate follows G6: a rank or a knowledge cost (blue), never both. "Essential for" feeds 1 Budget check.
A4: Building | B4: Group | C4: What it does | D4: Gate | E4: Knowledge | F4: Cost (proposed) | G4: Workers | H4: Runs on | I4: Essential for | J4: Change from today | K4: Your notes
A5: Storage & logistics | F5: —
A6: Settlers' Camp | B6: Storage & logistics | C6: Shelter for eight and the settlers' store until houses and a storehouse stand. | D6: start | F6: — | G6: 0 | H6: —
A7: Storehouse | B7: Storage & logistics | C7: Stores 300 materials; its haulers fetch from workplaces. | D7: start | F7: 8 timber | G7: 2 | H7: —
A8: Granary | B8: Storage & logistics | C8: Stores 300 food. | D8: start | F8: 8 timber | G8: 2 | H8: —
A9: Silo | B9: Storage & logistics | C9: Keeps 1000 grain dry, so granaries stay free. | E9: 1 | F9: 5 timber, 4 stone | G9: 0 | H9: — | J9: Was Village rank.
A10: Draught Stable | B10: Storage & logistics | C10: Stalls for pack up to 3 horses and oxen. | E10: 2 | F10: 8 timber, 4 planks | G10: 0 | J10: Was open from the start. | K10: runs on nothing, not to mix with Noble stable
A11: Builder's Yard | B11: Storage & logistics | C11: With its ox, building sites nearby rise half as fast again. | E11: 3 | F11: 8 timber, 4 planks, 3 stone | G11: 2 | H11: wood parts | J11: Was open from the start. Waits for a Draught Stable: an exception to G7, like the Cooper.
A12: Water, food & drink
A13: Well | B13: Water, food & drink | C13: Water for homes nearby (Timber House need). | D13: start | F13: 3 stone | G13: 0 | H13: — | I13: Timber House
A14: Market | B14: Water, food & drink | C14: Stalls; each open stall serves ten households with their goods (Townhouse need). | D14: start | F14: free | G14: Depends on space for stalls (up to 1 workspace/stall for every 2 sqares) | H14: — | I14: Timber House | K14: Amount of houses served depend on number of workers
A15: Alehouse | B15: Water, food & drink | C15: Pours drink for homes nearby (Townhouse need). Enlarged into a Tavern once a Town: twice the reach. | D15: Town | F15: 4 timber, 1 planks | G15: 2 | H15: ale, cider, mead or wine | I15: Townhouse | J15: Was Village rank. Its drink is now a Townhouse need, not a Timber House one. | K15: Amount of houses served depend on number of workers
A16: Bathhouse (proposal) | B16: Water, food & drink | C16: Hot baths: a Merchant's House need, and cheer for homes nearby. | D16: Borough | F16: 5 stone, 3 planks, 2 tiles, 1 glass | G16: 2 | H16: fuel, a little | I16: Merchant's House | J16: New. Opens at Borough, with the Merchant's House that needs it. | K16: Amount of houses served depend on number of workers
A17: Trade
A18: Trading Post | B18: Trade | C18: Import and export orders; animals are bought here. | D18: start | F18: 8 timber | G18: 2 | H18: wood parts | J18: Was Village rank: the Hamlet can trade (0 Stages). | K18: No planks needed, no wood part upkeep
A19: Dock | B19: Trade | C19: Boats carry more and trade cheaper; on the water's edge. | E19: 4 | F19: 8 planks, 5 timber, 3 stone | G19: 3 | H19: wood parts | J19: Was Village rank.
A20: Faith & learning
A21: Wooden Church | B21: Faith & learning | C21: Happiness in a wide area; 0.25 knowledge a month (Timber House need). | D21: Village | F21: 10 timber, 5 planks, 10 coins | G21: 1 | H21: — | I21: Timber House | J21: Was Town. | K21: Let's limit 1/city of this or its upgrades
A22: Stone Church (rebuild) | B22: Faith & learning | C22: More happiness, prestige and knowledge (1 a month);Townhouse need. | D22: Town | F22: 8 stone, 4 tiles, 1 tools, 20 coins | G22: 1 | H22: — | I22: Townhouse | J22: Mortar and glass in place of planks and rough stone. | K22: intermediate church
A23: Dressed Stone Church (upgrade) | B23: Faith & learning | C23: More happiness, prestige and knowledge (2 a month);Merchan'ts House need. | D23: Borough | F23: 8 dressed stone, 3 mortar, 1 glass, 1 tools, 20 coins | I23: Merchant's House | K23: Now the final level
A24: Monastery | B24: Faith & learning | C24: Reads a book a month: 3 knowledge, a little prestige, +3 happiness town-wide. | E24: 10 | F24: 10 stone, 8 planks, 5 tiles, 3 mortar, 30 coins | G24: 2 | H24: 1 book a month | J24: Was Town rank; mortar added.
A25: Public School (proposal) | B25: Faith & learning | C25: 0.02 learning per house, efficiency malus of 3% | E25: 2 | F25: 5 planks, 3 tiles, 3 stone | G25: 1 | H25: — | J25: New. The Sunday school is its alternative, as a church extension (step 4). Let's keep both
A26: Scriptorium | B26: Faith & learning | C26: Copies books from paper and leather. Makes books and knowledge | D26: charter | F26: 4 dressed stone, 4 planks, 8 coins | G26: 3 | H26: paper, leather | J26: Books only: paper moves to the Paper Mill.
A27: Administration
A28: Manor (hall) | B28: Administration | C28: The lord's seat. Taxes start only once it stands, and it can tax up to 45 villagers. | D28: Hamlet | F28: 10 timber, 4 planks, 5 coins | G28: 0 | H28: — | J28: Taxes need it now; was optional. Reviewed with the manor (step 5).
A29: Courthouse | B29: Administration | D29: Borough | F29: 8 dressed stone, 4 mortar, 4 planks, 20 coins | K29: Starting at borough, increased population exponentially diminishes hapines without policiment
A30: Tax Office | B30: Administration | C30: Taxes 40 more villagers. Short of paper it manages only half; tally sticks (timber) can stand in at half. | D30: Town | E30: 4 | F30: 5 planks, 3 stone, 8 coins | G30: 2 | H30: 2 paper a month | I30: Administrative buildings | J30: New (your G5 note).
A31: Health
A32: Apothecary | B32: Health | C32: Herbs into medicine (in 1 Basic lines). | E32: 4 | F32: 4 timber, 3 planks | G32: 2 | H32: herbs + fuel | I32: Townhouse | J32: Listed here for completeness; its gate lives in 1 Basic lines.
A34: The Apothecary is counted in 1 Basic lines only (its row here is informational and is left out of the budget check).
A35: Taxes: before a manor, no taxes at all; a Hamlet lives on its stock and what it sells. Manor up to 45 villagers; each Tax Office 40 more.

Sheet 2 Costs
A1: Construction costs on the new scale
A2: Today's costs divided by about four (G19) and rounded, with the changes from steps 1-2. Blue numbers are yours to change; the checks on the right follow them.
A4: Building | B4: Group | C4: Cost today | D4: Timber | E4: Planks | F4: Wood parts | G4: Stone | H4: Dressed stone | I4: Tiles | J4: Mortar | K4: Glass | L4: Stained glass | M4: Tools | N4: Books | O4: Coins | P4: Materials | Q4: Units | R4: G12 (max 4) | S4: Notes | T4: Your notes
A5: Homes
A6: Cottage | B6: Homes | C6: 12 timber | D6: 4 | P6: =COUNT(D6:N6) | Q6: =SUM(D6:N6) | R6: =IF(P6<=4,"OK","Too many")
A7: Timber House (upgrade) | B7: Homes | C7: 12 planks, 6 timber | D7: 2 | E7: 4 | P7: =COUNT(D7:N7) | Q7: =SUM(D7:N7) | R7: =IF(P7<=4,"OK","Too many")
A8: Townhouse (upgrade) | B8: Homes | C8: 20 planks, 15 tiles, 10 stone | E8: 6 | G8: 4 | I8: 10 | P8: =COUNT(D8:N8) | Q8: =SUM(D8:N8) | R8: =IF(P8<=4,"OK","Too many") | S8: Tools dropped (your edit).
A9: Merchant's House (upgrade) | B9: Homes | C9: 10 dressed stone, 20 tiles, 10 mortar, 5 glass, 20 coins | H9: 6 | I9: 10 | J9: 4 | K9: 4 | O9: 20 | P9: =COUNT(D9:N9) | Q9: =SUM(D9:N9) | R9: =IF(P9<=4,"OK","Too many")
A10: Patrician House (upgrade) | B10: Homes | C10: 20 dressed stone, 15 mortar, 4 stained glass, 100 coins | H10: 6 | J10: 4 | K10: 10 | L10: 6 | O10: 100 | P10: =COUNT(D10:N10) | Q10: =SUM(D10:N10) | R10: =IF(P10<=4,"OK","Too many")
A11: Production: timber, stone & earth
A12: Woodcutter's Lodge | B12: Production | C12: 15 timber | D12: 5 | P12: =COUNT(D12:N12) | Q12: =SUM(D12:N12) | R12: =IF(P12<=4,"OK","Too many")
A13: Forester's Hut | B13: Production | C13: 8 timber | D13: 5 | P13: =COUNT(D13:N13) | Q13: =SUM(D13:N13) | R13: =IF(P13<=4,"OK","Too many")
A14: Sawpit | B14: Production | C14: 25 timber | D14: 4 | P14: =COUNT(D14:N14) | Q14: =SUM(D14:N14) | R14: =IF(P14<=4,"OK","Too many")
A15: Carpenter's Workshop | B15: Production | C15: 15 timber, 10 planks | D15: 4 | E15: 4 | P15: =COUNT(D15:N15) | Q15: =SUM(D15:N15) | R15: =IF(P15<=4,"OK","Too many")
A16: Cooper's Workshop | B16: Production | C16: 15 timber, 10 planks | D16: 4 | E16: 4 | P16: =COUNT(D16:N16) | Q16: =SUM(D16:N16) | R16: =IF(P16<=4,"OK","Too many")
A17: Stone Quarry | B17: Production | C17: 20 timber | D17: 5 | P17: =COUNT(D17:N17) | Q17: =SUM(D17:N17) | R17: =IF(P17<=4,"OK","Too many")
A18: Clay Pit | B18: Production | C18: 15 timber | D18: 4 | P18: =COUNT(D18:N18) | Q18: =SUM(D18:N18) | R18: =IF(P18<=4,"OK","Too many")
A19: Tile Kiln | B19: Production | C19: 15 timber, 8 stone | D19: 4 | G19: 4 | P19: =COUNT(D19:N19) | Q19: =SUM(D19:N19) | R19: =IF(P19<=4,"OK","Too many")
A20: Stonemason's Yard | B20: Production | C20: 20 timber, 4 stone | D20: 4 | G20: 2 | P20: =COUNT(D20:N20) | Q20: =SUM(D20:N20) | R20: =IF(P20<=4,"OK","Too many")
A21: Sand Pit | B21: Production | C21: 15 timber | D21: 4 | P21: =COUNT(D21:N21) | Q21: =SUM(D21:N21) | R21: =IF(P21<=4,"OK","Too many")
A22: Lime Kiln | B22: Production | C22: 20 stone, 10 timber | D22: 3 | G22: 6 | P22: =COUNT(D22:N22) | Q22: =SUM(D22:N22) | R22: =IF(P22<=4,"OK","Too many")
A23: Potter's Workshop | B23: Production | C23: 15 timber, 8 stone, 30 coins | D23: 4 | E23: 6 | G23: 2 | O23: 15 | P23: =COUNT(D23:N23) | Q23: =SUM(D23:N23) | R23: =IF(P23<=4,"OK","Too many")
A24: Production: food & farming
A25: Farmstead | B25: Production | C25: 25 timber | D25: 6 | P25: =COUNT(D25:N25) | Q25: =SUM(D25:N25) | R25: =IF(P25<=4,"OK","Too many")
A26: Windmill | B26: Production | C26: 25 timber, 4 wood parts | D26: 6 | F26: 4 | P26: =COUNT(D26:N26) | Q26: =SUM(D26:N26) | R26: =IF(P26<=4,"OK","Too many")
A27: Bakery | B27: Production | C27: 20 timber, 4 stone | D27: 4 | E27: 8 | G27: 2 | P27: =COUNT(D27:N27) | Q27: =SUM(D27:N27) | R27: =IF(P27<=4,"OK","Too many")
A28: Watermill | B28: Production | C28: 30 timber, 15 stone, 6 wood parts | D28: 14 | F28: 10 | G28: 4 | O28: 10 | P28: =COUNT(D28:N28) | Q28: =SUM(D28:N28) | R28: =IF(P28<=4,"OK","Too many")
A29: Brewhouse | B29: Production | C29: 20 timber, 10 planks | D29: 4 | E29: 8 | P29: =COUNT(D29:N29) | Q29: =SUM(D29:N29) | R29: =IF(P29<=4,"OK","Too many")
A30: Animal Farm | B30: Production | C30: 30 timber, 5 planks | D30: 6 | E30: 2 | P30: =COUNT(D30:N30) | Q30: =SUM(D30:N30) | R30: =IF(P30<=4,"OK","Too many")
A31: Dairy | B31: Production | C31: 20 timber | D31: 4 | E31: 6 | P31: =COUNT(D31:N31) | Q31: =SUM(D31:N31) | R31: =IF(P31<=4,"OK","Too many")
A32: Orchard Keeper's Lodge | B32: Production | C32: 20 timber, 5 planks | D32: 4 | E32: 2 | P32: =COUNT(D32:N32) | Q32: =SUM(D32:N32) | R32: =IF(P32<=4,"OK","Too many")
A33: Beekeeper | B33: Production | C33: free | D33: 2 | E33: 6 | O33: 15 | P33: =COUNT(D33:N33) | Q33: =SUM(D33:N33) | R33: =IF(P33<=4,"OK","Too many") | S33: New.
A34: Forager's Hut | B34: Production | C34: 10 timber | D34: 5 | P34: =COUNT(D34:N34) | Q34: =SUM(D34:N34) | R34: =IF(P34<=4,"OK","Too many")
A35: Hunting Camp | B35: Production | C35: 15 timber | D35: 5 | P35: =COUNT(D35:N35) | Q35: =SUM(D35:N35) | R35: =IF(P35<=4,"OK","Too many")
A36: Fisher's Hut | B36: Production | C36: 15 timber | D36: 5 | P36: =COUNT(D36:N36) | Q36: =SUM(D36:N36) | R36: =IF(P36<=4,"OK","Too many")
A37: Production: crafts & metal
A38: Apothecary | B38: Production | C38: 15 timber, 10 planks | E38: 8 | H38: 4 | I38: 8 | O38: 10 | P38: =COUNT(D38:N38) | Q38: =SUM(D38:N38) | R38: =IF(P38<=4,"OK","Too many")
A39: Weaver | B39: Production | C39: 20 timber, 5 planks | D39: 4 | E39: 8 | P39: =COUNT(D39:N39) | Q39: =SUM(D39:N39) | R39: =IF(P39<=4,"OK","Too many")
A40: Tailor & Cobbler | B40: Production | C40: 15 timber, 10 planks | D40: 4 | E40: 6 | G40: 2 | P40: =COUNT(D40:N40) | Q40: =SUM(D40:N40) | R40: =IF(P40<=4,"OK","Too many")
A41: Tannery | B41: Production | C41: 25 timber | D41: 4 | E41: 4 | P41: =COUNT(D41:N41) | Q41: =SUM(D41:N41) | R41: =IF(P41<=4,"OK","Too many")
...

Sheet 2 Upkeep
A1: Upkeep: tools and wood parts worn a year at a full crew
A2: Today's rates read from the game; proposed rates in blue. Simple buildings wear at most a tool a year (your note).
A4: Building | B4: Kind | C4: Wears | D4: Today a month | E4: Today a year | F4: Proposed a year | G4: Proposed a month | H4: Change | I4: Your notes
A5: Simple buildings (at most 1 a year)
A6: Woodcutter's Lodge | B6: Simple buildings | C6: tools | D6: 0.15 | E6: =D6*12 | F6: 1 | G6: =F6/12
A7: Forester's Hut | B7: Simple buildings | C7: tools | D7: 0.05 | E7: =D7*12 | F7: 0.5 | G7: =F7/12
A8: Stone Quarry | B8: Simple buildings | C8: tools | D8: 0.2 | E8: =D8*12 | F8: 1.5 | G8: =F8/12
A9: Clay Pit | B9: Simple buildings | C9: tools | D9: 0.05 | E9: =D9*12 | F9: 0.5 | G9: =F9/12
A10: Sand Pit | B10: Simple buildings | C10: tools | D10: 0.05 | E10: =D10*12 | F10: 0.5 | G10: =F10/12
A11: Farmstead | B11: Simple buildings | C11: tools | D11: 0.1 | E11: =D11*12 | F11: 1 | G11: =F11/12
A12: Orchard Keeper's Lodge | B12: Simple buildings | C12: tools | D12: 0.05 | E12: =D12*12 | F12: 0.5 | G12: =F12/12
A13: Sawpit | B13: Simple buildings | C13: tools | D13: 0.15 | E13: =D13*12 | F13: 1 | G13: =F13/12
A14: Village workshops
A15: Windmill | B15: Village workshops | C15: wood parts | D15: 0.25 | E15: =D15*12 | F15: 3 | G15: =F15/12
A16: Watermill | B16: Village workshops | C16: wood parts | D16: 0.3 | E16: =D16*12 | F16: 6 | G16: =F16/12
A17: Brewhouse | B17: Village workshops | C17: wood parts | D17: 0.05 | E17: =D17*12 | F17: 1 | G17: =F17/12
A18: Weaver | B18: Village workshops | C18: wood parts | D18: 0.1 | E18: =D18*12 | F18: 1.5 | G18: =F18/12
A19: Dyer's Workshop | B19: Village workshops | C19: wood parts | D19: 0.05 | E19: =D19*12 | F19: 2 | G19: =F19/12
A20: Potter's Workshop | B20: Village workshops | C20: wood parts | D20: 0.1 | E20: =D20*12 | F20: 2 | G20: =F20/12
A21: Trading Post | B21: Village workshops | C21: wood parts | D21: 0.1 | E21: =D21*12 | F21: 0 | G21: =F21/12 | H21: No upkeep (your edit).
A22: Dock | B22: Village workshops | C22: wood parts | D22: 0.2 | E22: =D22*12 | F22: 3 | G22: =F22/12
A23: Winery | B23: Village workshops | C23: wood parts | D23: 0.15 | E23: =D23*12 | F23: 4 | G23: =F23/12
A24: Town workshops
A25: Carpenter's Workshop | B25: Town workshops | C25: tools | D25: 0.1 | E25: =D25*12 | F25: 4 | G25: =F25/12
A26: Cooper's Workshop | B26: Town workshops | C26: tools | D26: 0.1 | E26: =D26*12 | F26: 8 | G26: =F26/12
A27: Stonemason's Yard | B27: Town workshops | C27: tools | D27: 0.2 | E27: =D27*12 | F27: 10 | G27: =F27/12
A28: Tile Kiln | B28: Town workshops | C28: tools | D28: 0.05 | E28: =D28*12 | F28: 2 | G28: =F28/12
A29: Lime Kiln | B29: Town workshops | C29: tools | D29: 0.05 | E29: =D29*12 | F29: 2 | G29: =F29/12
A30: Charcoal Burner | B30: Town workshops | C30: tools | D30: 0.05 | E30: =D30*12 | F30: 1 | G30: =F30/12
A31: Glassworks | B31: Town workshops | C31: tools | D31: 0.1 | E31: =D31*12 | F31: 9 | G31: =F31/12
A32: Bog Iron Pit | B32: Town workshops | C32: tools | D32: 0.25 | E32: =D32*12 | F32: 2 | G32: =F32/12
A33: Bloomery | B33: Town workshops | C33: tools | D33: 0.1 | E33: =D33*12 | F33: 5 | G33: =F33/12
A34: Blacksmith | B34: Town workshops | C34: tools | D34: 0.1 | E34: =D34*12 | F34: 6 | G34: =F34/12
A35: Armoury | B35: Town workshops | C35: tools | D35: 0.15 | E35: =D35*12 | F35: 6 | G35: =F35/12 | H35: Moves to the manor (step 5).
A36: Jeweller's Shop | B36: Town workshops | C36: tools | D36: 0.1 | E36: =D36*12 | F36: 10 | G36: =F36/12
A37: Tannery | B37: Town workshops | C37: tools | D37: 0.05 | E37: =D37*12 | F37: 1 | G37: =F37/12
A38: Tailor & Cobbler | B38: Town workshops | C38: tools | D38: 0.05 | E38: =D38*12 | F38: 3 | G38: =F38/12
A39: Builder's Yard (its ox cart) | B39: Civic | C39: wood parts | D39: 1 | E39: =D39*12 | F39: 8 | G39: =F39/12 | H39: A wood part every three months instead of every month.
A41: Settlers' tools: two years of a regular set of simple buildings
A42: Woodcutter | B42: 2 | C42: =B42*SUMIF($A$5:$A$39,"Woodcutter's Lodge",$F$5:$F$39)*2
...

Sheet Crew audit
A1: What scales with the crew today (code check)
A2: Read from the game's code as it stands. Rows marked "No" are fixed in the rework (G20).
A4: What | B4: Scales with crew today? | C4: How it works now | D4: In the rework
A5: Workshop and gatherer output | B5: Yes | C5: Work per day = filled places / places, times walking efficiency, mood, learning and worn gear. | D5: Keep.
A6: Upkeep (tools, wood parts) | B6: Yes | C6: Wear per day = rate times filled share of the crew. | D6: Keep.
A7: Farm fields | B7: Yes | C7: Crop growth = farmers at work / tiles to tend. | D7: Keep.
A8: Herds | B8: Yes | C8: Herders' share of the crew scales the yield. | D8: Keep.
A9: Orchard picking | B9: Yes | C9: Fruit picked = pickers times a daily rate. | D9: Keep.
A10: Market stalls | B10: Yes | C10: Each stallholder opens one stall serving ten households. | D10: Keep; maximum stalls also depend on space (your note).
A11: Alehouse / tavern | B11: No | C11: Pours for every home in reach as soon as one tapster works. | D11: Homes served by tapsters at work (your note).
A12: Trading post and dock | B12: No | C12: Full monthly cargo with a single worker. | D12: Cargo by the crew at work.
A13: Storehouse and granary haulers | B13: No | C13: One hauler anywhere and every workplace's goods are fetched. | D13: Each hauler fetches so many loads a day.
A14: Builder's yard | B14: No | C14: Full speed-up with any worker and its ox. | D14: Speed-up by the crew at work.
A15: Monastery, university | B15: No | C15: Fed with books and anyone at work: full knowledge and prestige. | D15: Knowledge by the crew at work.
... A18: Stable, watchtower | B18: No | C18: One groom or watchman: on or off. | D18: Fine with one place; stays.

Sheet 3 Mixed & late
A1: Step 3: mixed industry and late goods
A2: Workshops that join two lines, and the goods at the end of every chain. Same gate rule (G6).
A4: Line | B4: Unlock | C4: Kind | D4: Makes | E4: From | F4: Gate | G4: Knowledge | H4: Upkeep | I4: Essential for | J4: Why | K4: Change from today | L4: Your notes
A5: Garments | B5: Embroiderer | C5: Building | D5: fine clothes | E5: cloth, dyes | G5: 10 | H5: tools | I5: Patrician House | J5: Fine clothes get their own building (G16): dyed cloth, embroidered. | K5: Was a tailor recipe.
A6: Glass | B6: Glazier's Workshop | C6: Building | D6: stained glass | E6: glass, dyes | G6: 10 | H6: tools | I6: Patrician House | J6: Coloured panes leaded into windows: churches, the cathedral, the finest homes. | K6: Was a glassworks recipe.
A7: Writing | B7: Tanner: parchment | C7: Recipe | D7: parchment | E7: hides | G7: 3 | J7: A second writing material: feeds offices and books as well as paper does, but costs hides. | K7: New good. Hides get a second use.
A8: Writing | B8: Scriptorium (charter) | C8: Building | D8: books, knowledge | E8: paper or parchment, leather | F8: charter | H8: tools | J8: Books stay a charter craft; other towns buy them. | K8: Books from parchment as well as paper.
A9: Drink | B9: Brewhouse: mead | C9: Recipe | D9: mead | E9: honey + fuel | G9: 3 | J9: With the beekeeper every town has honey; mead becomes a third tavern drink. | K9: Was charter-only. Meadmakers now doubles honey and mead instead.
A10: Drink | B10: Winery (charter) | C10: Building | D10: wine | E10: grapes, crates | F10: charter | H10: wood parts | J10: Wine stays the orchard charter's prize: a luxury and a drink.
A11: Metal | B11: Cooper (hoops) | C11: Building | D11: crates | E11: planks, iron | G11: 3 | H11: wood parts | J11: Iron hoops bind the staves: iron's second use. | K11: Iron added (your edit). Waits for trade (G7 exception).
A12: Metal | B12: Jeweller's Shop (charter) | C12: Building | D12: jewellery | E12: silver, glass | F12: charter | H12: tools | J12: Silver set with glass beads; silver is bought or comes with Deep Veins. | K12: Glass added as a second input.
A14: Removed: arms (the armoury becomes a manor building, step 5), oats, mushrooms. Not added on purpose: new raw goods. Silver stays bought (or the Deep Veins charter).

Sheet 3 Goods map
A1: Step 3: every good after the rework, its source and its uses
A2: Built by hand from steps 1-3. G14: foods are used by being eaten, intermediates need their chain, finished goods two uses.
A4: Good | B4: Kind | C4: Made by | D4: Used by | E4: Uses | F4: G14 | G4: Your notes
A5: Building materials
A6: Timber | B6: material | C6: Woodcutter | D6: build costs; sawmill; charcoal burner; blacksmith | E6: 4 | F6: OK
A7: Firewood | B7: fuel | C7: Woodcutter | D7: home heating; fuel for every fire workshop (G18) | E7: 2 | F7: OK
A8: Planks | B8: material | C8: Sawmill | D8: build costs; carpenter; cooper | E8: 3 | F8: OK
A9: Wood parts | B9: material | C9: Carpenter | D9: build costs; upkeep | E9: 2 | F9: OK
A10: Stone | B10: material | C10: Quarry | D10: build costs; stonemason; lime kiln; stone roads | E10: 4 | F10: OK
A11: Dressed stone | B11: material | C11: Stonemason | D11: build costs; cobbled streets | E11: 2 | F11: OK
A12: Clay | B12: intermediate | C12: Clay Pit | D12: kiln; potter | E12: 2 | F12: OK
A13: Tiles | B13: material | C13: Kiln | D13: build costs (homes, churches, civic) | E13: 1 | F13: OK: many build costs
